Workbook

Sheet Scale completeness
A1: Scale | B1: ARIC | C1: CHS | D1: FHS | E1: JHS | F1: MESA
A2: Brim | B2: =Brim!C6 -> 0.5 | C2: =Brim!D6 -> 0.5 | D2: =Brim!E6 -> 0.25 | E2: =Brim!F6 -> 0.75 | F2: =Brim!G6 -> 1
A3: BSNI | B3: =BSNI!C13 -> 0.63636364 | C3: =BSNI!D13 -> 0.81818182 | D3: =BSNI!E13 -> 1 | E3: =BSNI!F13 -> 0.90909091 | F3: =BSNI!G13 -> 0.54545455
A4: CHS social network | B4: ='CHS Scores'!C13 -> 0.9 | C4: ='CHS Scores'!D13 -> 0.8 | D4: ='CHS Scores'!E13 -> 0.6 | E4: ='CHS Scores'!F13 -> 0.9 | F4: ='CHS Scores'!G13 -> 0.2
A5: CHS social support | B5: ='CHS Scores'!C20 -> 1 | C5: ='CHS Scores'!D20 -> 1 | D5: ='CHS Scores'!E20 -> 0.6 | E5: ='CHS Scores'!F20 -> 1 | F5: ='CHS Scores'!G20 -> 0.6
A6: ESSI | B6: =ESSI!C7 -> 0.6 | C6: =ESSI!D7 -> 0.8 | D6: =ESSI!E7 -> 0.8 | E6: =ESSI!F7 -> 0.6 | F6: =ESSI!G7 -> 1
A7: HALFt | B7: =HALFt!C7 -> 0.8 | C7: =HALFt!D7 -> 0.8 | D7: =HALFt!E7 -> 0.6 | E7: =HALFt!F7 -> 1 | F7: =HALFt!G7 -> 0.4
A8: ISEL | B8: =ISEL!C19 -> 1 | C8: =ISEL!D19 -> 0.64705882 | D8: =ISEL!E19 -> 0.35294118 | E8: =ISEL!F19 -> 0.94117647 | F8: =ISEL!G19 -> 0.23529412
A9: Makizako | B9: =Makizako!C7 -> 0.4 | C9: =Makizako!D7 -> 0.4 | D9: =Makizako!E7 -> 0.2 | E9: =Makizako!F7 -> 0.4 | F9: =Makizako!G7 -> 0.2
A10: FRAIL | B10: =FRAIL!C17 -> 1 | C10: =FRAIL!D17 -> 1 | D10: =FRAIL!E17 -> 1 | E10: =FRAIL!F17 -> 0.93333333 | F10: =FRAIL!G17 -> 1
A11: Fried | B11: =Fried!C8 -> 1 | C11: =Fried!D8 -> 1 | D11: =Fried!E8 -> 1 | E11: =Fried!F8 -> 0.66666667 | F11: =Fried!G8 -> 0.66666667
A12: Rockwood | B12: =Rockwood!C35 -> 0.96969697 | C12: =Rockwood!D35 -> 0.90909091 | D12: =Rockwood!E35 -> 0.96969697 | E12: =Rockwood!F35 -> 0.66666667 | F12: =Rockwood!G35 -> 0.57575758
A13: Tilburg | B13: =Tilburg!C16 -> 0.92857143 | C13: =Tilburg!D16 -> 0.92857143 | D13: =Tilburg!E16 -> 0.85714286 | E13: =Tilburg!F16 -> 0.64285714 | F13: =Tilburg!G16 -> 0.42857143
A14: FIFE | B14: =Fried!C8 -> 1 | C14: =Fried!D8 -> 1 | D14: =Fried!E8 -> 1 | E14: =Fried!F8 -> 0.66666667 | F14: =Fried!G8 -> 0.66666667
A15: Barthe | B15: =Barthe!C13 -> 0.90909091 | C15: =Barthe!D13 -> 0.90909091 | D15: =Barthe!E13 -> 0.90909091 | E15: =Barthe!F13 -> 0.27272727 | F15: =Barthe!G13 -> 0.36363636
A16: Lubben | B16: ='Lubben SNS'!C13 -> 1 | C16: ='Lubben SNS'!D13 -> 1 | D16: ='Lubben SNS'!E13 -> 0.63636364 | E16: ='Lubben SNS'!F13 -> 0.72727273 | F16: ='Lubben SNS'!G13 -> 0.27272727

Sheet All scales all studies
B1: ESSI | C1: Berkman SN | D1: Makizako | E1: HALFt | F1: Brim | G1: CHS scores | H1: ISELF | I1: FRAIL | J1: Fried | K1: Rockwood | L1: Barthel | M1: Katz | N1: FIFE | O1: Tilburg | P1: Lubben | R1: ARIC | S1: CHS | T1: FHS | U1: JHS | V1: MESA
A2: Talks to with someone exery day | D2: X | R2: 0 | S2: 0 | T2: 0 | U2: 0 | V2: 0
A3: Often talks to fam/friends | E3: X | G3: X | H3: X | R3: X | S3: X | T3: X | U3: X | V3: 0
A4: # Close friends | C4: X | G4: X | P4: X | R4: X | S4: X | T4: X | U4: X | V4: 0
A5: # Close friends/mo | C5: X | G5: X | H5: X | P5: X | R5: X | S5: X | T5: X | U5: X | V5: 0
A6: How often see friend with most contact? | G6: X | P6: X | R6: X | S6: X | T6: 0 | U6: 0 | V6: 0
A7: # close relatives | P7: X | R7: X | S7: X | T7: X | U7: X | V7: 0
A8: # relatives once/month | C8: X | G8: X | P8: X | R8: X | S8: X | T8: X | U8: X | V8: 0
A9: How often see relative with most contaact | C9: X | G9: X | H9: X | P9: X | R9: X | S9: X | T9: 0 | U9: X | V9: 0
A10: Misses people/lonely | D10: X | E10: X | O10: X | R10: X | S10: X | T10: X | U10: X | V10: X
A11: Has someone to talk to when lonely. | H11: X | R11: X | S11: X | T11: 0 | U11: X | V11: 0
A12: Has someone that shoes love/affection | B12: X | C12: X | R12: 0 | S12: 0 | T12: X | U12: X | V12: X
A13: Someone to provide objective view | H13: X | R13: X | S13: 0 | T13: 0 | U13: X | V13: 0
A14: Trust at least one person's advice | G14: X | P14: X | R14: X | S14: X | T14: X | U14: X | V14: X
A15: Trust at least one person's financial advice | B15: X | C15: X | G15: X | H15: X | R15: X | S15: X | T15: 0 | U15: X | V15: 0
A16: Has someone who can help with a serious/personal problem. | F16: X | G16: X | P16: X | R16: X | S16: X | T16: X | U16: X | V16: X
A17: Has someone they can trust/confidant | B17: X | C17: X | F17: X | G17: X | H17: X | P17: X | R17: X | S17: X | T17: X | U17: 0 | V17: X
A18: Has an emotional supporter | B18: X | C18: X | G18: X | R18: 0 | S18: X | T18: X | U18: 0 | V18: X
A19: Receives enough support from others | O19: X | R19: 0 | S19: 0 | T19: 0 | U19: X | V19: 0
A20: Friends are more interesting | H20: X | R20: X | S20: 0 | T20: 0 | U20: X | V20: 0
A21: Has hard time keeping pace with friends | H21: X | R21: X | S21: 0 | T21: 0 | U21: X | V21: 0
A22: Stopped visiting friends | D22: X | R22: 0 | S22: 0 | T22: 0 | U22: 0 | V22: 0
A23: Stopped going out | D23: X | R23: 0 | S23: 0 | T23: 0 | U23: 0 | V23: 0
A24: Often feels excluded by friends | H24: X | R24: X | S24: 0 | T24: 0 | U24: X | V24: 0
A25: Feels not invited to things | H25: X | R25: X | S25: 0 | T25: 0 | U25: X | V25: 0
A26: If sick, can find someone for chores | B26: X | G26: X | H26: X | R26: X | S26: X | T26: 0 | U26: X | V26: X
A27: Someone to take care of house when out of town | H27: X | R27: X | S27: X | T27: 0 | U27: X | V27: 0
A28: Borrow someone's car for a few hours | H28: X | R28: X | S28: X | T28: 0 | U28: X | V28: 0
A29: Has somone to help when sick (e.g. take to doctor) | H29: X | R29: X | S29: 0 | T29: 0 | U29: X | V29: 0
A30: Others talk to you about important decisions | G30: X | P30: X | R30: X | S30: X | T30: 0 | U30: 0 | V30: 0
A31: Assist others in their ADLs | G31: X | R31: X | S31: X | T31: 0 | U31: X | V31: 0
A32: Helps others in need | D32: X | E32: X | G32: X | P32: X | R32: X | S32: X | T32: 0 | U32: X | V32: 0
A33: How often do family/friends make too many demands of you? | F33: X | R33: 0 | S33: 0 | T33: 0 | U33: X | V33: X
A34: How often do family/friends let you down when you need them? | F34: X | R34: 0 | S34: 0 | T34: 0 | U34: X | V34: X
A35: Participates in groups | C35: X | E35: X | R35: 0 | S35: 0 | T35: X | U35: X | V35: 0
A36: Goes to church | C36: X | R36: 0 | S36: X | T36: X | U36: X | V36: X
A37: Living situation
A38: Marital status | C38: X | G38: X | R38: X | S38: X | T38: X | U38: X | V38: X
A39: Lives alone | G39: X | O39: X | R39: X | S39: X | T39: X | U39: X | V39: 0
A40: Has someone who relies on you | G40: X | R40: X | S40: X | T40: 0 | U40: 0 | V40: 0
...

Sheet Brim
B1: Brim | C1: ARIC | D1: CHS | E1: FHS | F1: JHS | G1: MESA
A2: ='All scales all studies'!A17 -> Has someone they can trust/confidant | B2: ='All scales all studies'!F17 -> X | C2: ='All scales all studies'!R17 -> X | D2: ='All scales all studies'!S17 -> X | E2: ='All scales all studies'!T17 -> X | F2: ='All scales all studies'!U17 -> 0 | G2: ='All scales all studies'!V17 -> X
A3: ='All scales all studies'!A33 -> How often do family/friends make too many demands of you? | B3: ='All scales all studies'!F33 -> X | C3: ='All scales all studies'!R33 -> 0 | D3: ='All scales all studies'!S33 -> 0 | E3: ='All scales all studies'!T34 -> 0 | F3: ='All scales all studies'!U33 -> X | G3: ='All scales all studies'!V33 -> X
A4: ='All scales all studies'!A34 -> How often do family/friends let you down when you need them? | B4: ='All scales all studies'!F34 -> X | C4: ='All scales all studies'!R34 -> 0 | D4: ='All scales all studies'!S34 -> 0 | E4: ='All scales all studies'!T34 -> 0 | F4: ='All scales all studies'!U34 -> X | G4: ='All scales all studies'!V34 -> X
A5: Has someone to help with serious problem | B5: ='All scales all studies'!F16 -> X | C5: ='All scales all studies'!R16 -> X | D5: ='All scales all studies'!S16 -> X | E5: ='All scales all studies'!T34 -> 0 | F5: ='All scales all studies'!U16 -> X | G5: ='All scales all studies'!V16 -> X
C6: =COUNTIF(C2:C5,"X")/COUNTIF($B2:$B5,"X") -> 0.5 | D6: =COUNTIF(D2:D5,"X")/COUNTIF($B2:$B5,"X") -> 0.5 | E6: =COUNTIF(E2:E5,"X")/COUNTIF($B2:$B5,"X") -> 0.25 | F6: =COUNTIF(F2:F5,"X")/COUNTIF($B2:$B5,"X") -> 0.75 | G6: =COUNTIF(G2:G5,"X")/COUNTIF($B2:$B5,"X") -> 1

Sheet CHS Scores
B1: CHS scores | C1: ARIC | D1: CHS | E1: FHS | F1: JHS | G1: MESA
A2: Social network Score
A3: # Close friends | B3: ='All scales all studies'!G4 -> X | C3: ='All scales all studies'!R4 -> X | D3: ='All scales all studies'!S4 -> X | E3: ='All scales all studies'!T4 -> X | F3: ='All scales all studies'!U4 -> X | G3: ='All scales all studies'!V4 -> 0
A4: # Close friends/mo | B4: ='All scales all studies'!G5 -> X | C4: ='All scales all studies'!R5 -> X | D4: ='All scales all studies'!S5 -> X | E4: ='All scales all studies'!T5 -> X | F4: ='All scales all studies'!U5 -> X | G4: ='All scales all studies'!V5 -> 0
A5: How often see friend with most contact | B5: ='All scales all studies'!G6 -> X | C5: ='All scales all studies'!R6 -> X | D5: ='All scales all studies'!S6 -> X | E5: ='All scales all studies'!T6 -> 0 | F5: ='All scales all studies'!U6 -> 0 | G5: ='All scales all studies'!V6 -> 0
A6: # relatives once/month | B6: ='All scales all studies'!G8 -> X | C6: ='All scales all studies'!R7 -> X | D6: ='All scales all studies'!S7 -> X | E6: ='All scales all studies'!T7 -> X | F6: ='All scales all studies'!U7 -> X | G6: ='All scales all studies'!V7 -> 0
A7: How often see relative with most contact | B7: ='All scales all studies'!G9 -> X | C7: ='All scales all studies'!R8 -> X | D7: ='All scales all studies'!S8 -> X | E7: ='All scales all studies'!T8 -> X | F7: ='All scales all studies'!U8 -> X | G7: ='All scales all studies'!V8 -> 0
A8: Has an emotional supporter | B8: ='All scales all studies'!G18 -> X | C8: ='All scales all studies'!R9 -> X | D8: ='All scales all studies'!S9 -> X | E8: ='All scales all studies'!T9 -> 0 | F8: ='All scales all studies'!U9 -> X | G8: ='All scales all studies'!V9 -> 0
A9: Lives alone | B9: ='All scales all studies'!G39 -> X | C9: ='All scales all studies'!R10 -> X | D9: ='All scales all studies'!S10 -> X | E9: ='All scales all studies'!T10 -> X | F9: ='All scales all studies'!U10 -> X | G9: ='All scales all studies'!V10 -> X
A10: People talk to you re: important decisions | B10: ='All scales all studies'!G30 -> X | C10: ='All scales all studies'!R11 -> X | D10: ='All scales all studies'!S11 -> X | E10: ='All scales all studies'!T11 -> 0 | F10: ='All scales all studies'!U11 -> X | G10: ='All scales all studies'!V11 -> 0
A11: Has someone who relies on you | B11: ='All scales all studies'!G40 -> X | C11: ='All scales all studies'!R12 -> 0 | D11: ='All scales all studies'!S12 -> 0 | E11: ='All scales all studies'!T12 -> X | F11: ='All scales all studies'!U12 -> X | G11: ='All scales all studies'!V12 -> X
A12: Help someone some else with ADLs | B12: ='All scales all studies'!G31 -> X | C12: ='All scales all studies'!R13 -> X | D12: ='All scales all studies'!S13 -> 0 | E12: ='All scales all studies'!T13 -> 0 | F12: ='All scales all studies'!U13 -> X | G12: ='All scales all studies'!V13 -> 0
C13: =COUNTIF(C2:C12,"X")/COUNTIF($B2:$B12,"X") -> 0.9 | D13: =COUNTIF(D2:D12,"X")/COUNTIF($B2:$B12,"X") -> 0.8 | E13: =COUNTIF(E2:E12,"X")/COUNTIF($B2:$B12,"X") -> 0.6 | F13: =COUNTIF(F2:F12,"X")/COUNTIF($B2:$B12,"X") -> 0.9 | G13: =COUNTIF(G2:G12,"X")/COUNTIF($B2:$B12,"X") -> 0.2
A14: Social support score
A15: When lonely, people to talk to | B15: X | C15: X | D15: ='All scales all studies'!S11 -> X | E15: ='All scales all studies'!T11 -> 0 | F15: ='All scales all studies'!U11 -> X | G15: ='All scales all studies'!V11 -> 0
A16: Often meet/talk with family/friends | B16: ='All scales all studies'!G14 -> X | C16: X | D16: ='All scales all studies'!S3 -> X | E16: ='All scales all studies'!T3 -> X | F16: ='All scales all studies'!U3 -> X | G16: ='All scales all studies'!V3 -> 0
A17: If sick, can find someone for chores | B17: ='All scales all studies'!G26 -> X | C17: X | D17: ='All scales all studies'!S26 -> X | E17: ='All scales all studies'!T26 -> 0 | F17: ='All scales all studies'!U26 -> X | G17: ='All scales all studies'!V26 -> X
A18: Know somebody to talk to for personal prob | B18: ='All scales all studies'!G16 -> X | C18: X | D18: ='All scales all studies'!S16 -> X | E18: ='All scales all studies'!T16 -> X | F18: ='All scales all studies'!U16 -> X | G18: ='All scales all studies'!V16 -> X
A19: Trust at least one person's advice | B19: ='All scales all studies'!G14 -> X | C19: X | D19: ='All scales all studies'!S14 -> X | E19: ='All scales all studies'!T14 -> X | F19: ='All scales all studies'!U14 -> X | G19: ='All scales all studies'!V14 -> X
C20: =COUNTIF(C14:C19,"X")/COUNTIF($B14:$B19,"X") -> 1 | D20: =COUNTIF(D14:D19,"X")/COUNTIF($B14:$B19,"X") -> 1 | E20: =COUNTIF(E14:E19,"X")/COUNTIF($B14:$B19,"X") -> 0.6 | F20: =COUNTIF(F14:F19,"X")/COUNTIF($B14:$B19,"X") -> 1 | G20: =COUNTIF(G14:G19,"X")/COUNTIF($B14:$B19,"X") -> 0.6

Sheet ISEL
B1: ISELF | C1: ARIC | D1: CHS | E1: FHS | F1: JHS | G1: MESA
A2: # Close friends/mo | B2: X | C2: ='All scales all studies'!R5 -> X | D2: ='All scales all studies'!S5 -> X | E2: ='All scales all studies'!T5 -> X | F2: ='All scales all studies'!U5 -> X | G2: ='All scales all studies'!V5 -> 0
A3: # relatives once/month | B3: X | C3: ='All scales all studies'!R8 -> X | D3: ='All scales all studies'!S8 -> X | E3: ='All scales all studies'!T8 -> X | F3: ='All scales all studies'!U8 -> X | G3: ='All scales all studies'!V8 -> 0
A4: Trust at least one person's advice | B4: X | C4: ='All scales all studies'!R14 -> X | D4: ='All scales all studies'!S14 -> X | E4: ='All scales all studies'!T14 -> X | F4: ='All scales all studies'!U14 -> X | G4: ='All scales all studies'!V14 -> X
A5: Has someone they can trust/confidant | B5: X | C5: ='All scales all studies'!R17 -> X | D5: ='All scales all studies'!S17 -> X | E5: ='All scales all studies'!T17 -> X | F5: ='All scales all studies'!U17 -> 0 | G5: ='All scales all studies'!V17 -> X
A6: If sick, can find someone for chores | B6: X | C6: ='All scales all studies'!R26 -> X | D6: ='All scales all studies'!S26 -> X | E6: ='All scales all studies'!T26 -> 0 | F6: ='All scales all studies'!U26 -> X | G6: ='All scales all studies'!V26 -> X
A7: Trust at least one person's financial advice | B7: X | C7: ='All scales all studies'!R15 -> X | D7: ='All scales all studies'!S15 -> X | E7: ='All scales all studies'!T15 -> 0 | F7: ='All scales all studies'!U15 -> X | G7: ='All scales all studies'!V15 -> 0
A8: Someone to provide objective view | B8: X | C8: ='All scales all studies'!R13 -> X | D8: ='All scales all studies'!S13 -> 0 | E8: ='All scales all studies'!T13 -> 0 | F8: ='All scales all studies'!U13 -> X | G8: ='All scales all studies'!V13 -> 0
A9: Someone to take care of house when out of town | B9: X | C9: ='All scales all studies'!R27 -> X | D9: ='All scales all studies'!S27 -> X | E9: ='All scales all studies'!T27 -> 0 | F9: ='All scales all studies'!U27 -> X | G9: ='All scales all studies'!V27 -> 0
A10: Borrow someone's car for a few hours | B10: X | C10: ='All scales all studies'!R28 -> X | D10: ='All scales all studies'!S28 -> X | E10: ='All scales all studies'!T28 -> 0 | F10: ='All scales all studies'!U28 -> X | G10: ='All scales all studies'!V28 -> 0
A11: Has someone to talk to when lonely. | B11: X | C11: ='All scales all studies'!R11 -> X | D11: ='All scales all studies'!S11 -> X | E11: ='All scales all studies'!T11 -> 0 | F11: ='All scales all studies'!U11 -> X | G11: ='All scales all studies'!V11 -> 0
A12: Often feels excluded by friends | B12: X | C12: ='All scales all studies'!R24 -> X | D12: ='All scales all studies'!S24 -> 0 | E12: ='All scales all studies'!T24 -> 0 | F12: ='All scales all studies'!U24 -> X | G12: ='All scales all studies'!V24 -> 0
A13: Feels not invited to things | B13: X | C13: ='All scales all studies'!R25 -> X | D13: ='All scales all studies'!S25 -> 0 | E13: ='All scales all studies'!T25 -> 0 | F13: ='All scales all studies'!U25 -> X | G13: ='All scales all studies'!V25 -> 0
A14: Friends are more interesting | B14: X | C14: ='All scales all studies'!R20 -> X | D14: ='All scales all studies'!S20 -> 0 | E14: ='All scales all studies'!T20 -> 0 | F14: ='All scales all studies'!U20 -> X | G14: ='All scales all studies'!V20 -> 0
A15: Feels satisfied with life | B15: X | C15: X | D15: X | E15: X | F15: X | G15: X
A16: Has hard time keeping pace with friends | B16: X | C16: ='All scales all studies'!R21 -> X | D16: ='All scales all studies'!S21 -> 0 | E16: ='All scales all studies'!T21 -> 0 | F16: ='All scales all studies'!U21 -> X | G16: ='All scales all studies'!V21 -> 0
A17: Often talks to fam/friends | B17: X | C17: ='All scales all studies'!R3 -> X | D17: ='All scales all studies'!S3 -> X | E17: ='All scales all studies'!T3 -> X | F17: ='All scales all studies'!U3 -> X | G17: ='All scales all studies'!V3 -> 0
A18: Has somone to help when sick (e.g. take to doctor) | B18: X | C18: ='All scales all studies'!R29 -> X | D18: ='All scales all studies'!S29 -> 0 | E18: ='All scales all studies'!T29 -> 0 | F18: ='All scales all studies'!U29 -> X | G18: ='All scales all studies'!V29 -> 0
C19: =COUNTIF(C2:C18,"X")/COUNTIF($B2:$B18,"X") -> 1 | D19: =COUNTIF(D2:D18,"X")/COUNTIF($B2:$B18,"X") -> 0.64705882 | E19: =COUNTIF(E2:E18,"X")/COUNTIF($B2:$B18,"X") -> 0.35294118 | F19: =COUNTIF(F2:F18,"X")/COUNTIF($B2:$B18,"X") -> 0.94117647 | G19: =COUNTIF(G2:G18,"X")/COUNTIF($B2:$B18,"X") -> 0.23529412

Sheet HALFt
B1: HALFt | C1: ARIC | D1: CHS | E1: FHS | F1: JHS | G1: MESA
A2: Participates in groups | B2: X | C2: ='All scales all studies'!R35 -> 0 | D2: ='All scales all studies'!S35 -> 0 | E2: ='All scales all studies'!T35 -> X | F2: ='All scales all studies'!U35 -> X | G2: ='All scales all studies'!V35 -> 0
A3: Often talks to fam/friends | B3: X | C3: ='All scales all studies'!R3 -> X | D3: ='All scales all studies'!S3 -> X | E3: ='All scales all studies'!T3 -> X | F3: ='All scales all studies'!U3 -> X | G3: ='All scales all studies'!V3 -> 0
A4: Misses people | B4: X | C4: ='All scales all studies'!R10 -> X | D4: ='All scales all studies'!S10 -> X | E4: ='All scales all studies'!T10 -> X | F4: ='All scales all studies'!U10 -> X | G4: ='All scales all studies'!V10 -> X
A5: Feels like has enough income | B5: X | C5: ='All scales all studies'!R41 -> X | D5: ='All scales all studies'!S41 -> X | E5: ='All scales all studies'!T41 -> 0 | F5: ='All scales all studies'!U41 -> X | G5: ='All scales all studies'!V41 -> X
A6: Helps others in need | B6: X | C6: ='All scales all studies'!R32 -> X | D6: ='All scales all studies'!S32 -> X | E6: ='All scales all studies'!T32 -> 0 | F6: ='All scales all studies'!U32 -> X | G6: ='All scales all studies'!V32 -> 0
C7: =COUNTIF(C2:C6,"X")/5 -> 0.8 | D7: =COUNTIF(D2:D6,"X")/5 -> 0.8 | E7: =COUNTIF(E2:E6,"X")/5 -> 0.6 | F7: =COUNTIF(F2:F6,"X")/5 -> 1 | G7: =COUNTIF(G2:G6,"X")/5 -> 0.4

Sheet ESSI
B1: ESSI | C1: ARIC | D1: CHS | E1: FHS | F1: JHS | G1: MESA
A2: Trust at least one person's advice | B2: X | C2: ='All scales all studies'!R14 -> X | D2: ='All scales all studies'!S14 -> X | E2: ='All scales all studies'!T14 -> X | F2: ='All scales all studies'!U14 -> X | G2: ='All scales all studies'!V14 -> X
A3: Has someone that shoes love/affection | B3: X | C3: ='All scales all studies'!R12 -> 0 | D3: ='All scales all studies'!S12 -> 0 | E3: ='All scales all studies'!T12 -> X | F3: ='All scales all studies'!U12 -> X | G3: ='All scales all studies'!V12 -> X
A4: Has an emotional supporter | B4: X | C4: ='All scales all studies'!R18 -> 0 | D4: ='All scales all studies'!S18 -> X | E4: ='All scales all studies'!T18 -> X | F4: ='All scales all studies'!U18 -> 0 | G4: ='All scales all studies'!V18 -> X
A5: Has someone they can trust/confidant | B5: X | C5: ='All scales all studies'!R17 -> X | D5: ='All scales all studies'!S17 -> X | E5: ='All scales all studies'!T17 -> X | F5: ='All scales all studies'!U17 -> 0 | G5: ='All scales all studies'!V17 -> X
A6: If sick, can find someone for chores | B6: X | C6: ='All scales all studies'!R26 -> X | D6: ='All scales all studies'!S26 -> X | E6: ='All scales all studies'!T26 -> 0 | F6: ='All scales all studies'!U26 -> X | G6: ='All scales all studies'!V26 -> X
C7: =COUNTIF(C2:C6,"X")/5 -> 0.6 | D7: =COUNTIF(D2:D6,"X")/5 -> 0.8 | E7: =COUNTIF(E2:E6,"X")/5 -> 0.8 | F7: =COUNTIF(F2:F6,"X")/5 -> 0.6 | G7: =COUNTIF(G2:G6,"X")/5 -> 1

Sheet BSNI
B1: BSNI | C1: ARIC | D1: CHS | E1: FHS | F1: JHS | G1: MESA
A2: # Close friends | B2: X | C2: ='All scales all studies'!R4 -> X | D2: ='All scales all studies'!S4 -> X | E2: ='All scales all studies'!T4 -> X | F2: ='All scales all studies'!U4 -> X | G2: ='All scales all studies'!V4 -> 0
A3: # Close friends/mo | B3: X | C3: ='All scales all studies'!R5 -> X | D3: ='All scales all studies'!S5 -> X | E3: ='All scales all studies'!T5 -> X | F3: ='All scales all studies'!U5 -> X | G3: ='All scales all studies'!V5 -> 0
A4: Close relatives | B4: X | C4: ='All scales all studies'!R7 -> X | D4: ='All scales all studies'!S7 -> X | E4: ='All scales all studies'!T7 -> X | F4: ='All scales all studies'!U7 -> X | G4: ='All scales all studies'!V7 -> 0
A5: # relatives once/month | B5: X | C5: ='All scales all studies'!R8 -> X | D5: ='All scales all studies'!S8 -> X | E5: ='All scales all studies'!T8 -> X | F5: ='All scales all studies'!U8 -> X | G5: ='All scales all studies'!V8 -> 0
A6: Participates in groups | B6: X | C6: ='All scales all studies'!R35 -> 0 | D6: ='All scales all studies'!S35 -> 0 | E6: ='All scales all studies'!T35 -> X | F6: ='All scales all studies'!U35 -> X | G6: ='All scales all studies'!V35 -> 0
A7: Goes to church | B7: X | C7: ='All scales all studies'!R36 -> 0 | D7: ='All scales all studies'!S36 -> X | E7: ='All scales all studies'!T36 -> X | F7: ='All scales all studies'!U36 -> X | G7: ='All scales all studies'!V36 -> X
A8: Marital status | B8: X | C8: ='All scales all studies'!R38 -> X | D8: ='All scales all studies'!S38 -> X | E8: ='All scales all studies'!T38 -> X | F8: ='All scales all studies'!U38 -> X | G8: ='All scales all studies'!V38 -> X
A9: Trust at least one person's advice | B9: X | C9: ='All scales all studies'!R14 -> X | D9: ='All scales all studies'!S14 -> X | E9: ='All scales all studies'!T14 -> X | F9: ='All scales all studies'!U14 -> X | G9: ='All scales all studies'!V14 -> X
A10: Has someone that shoes love/affection | B10: X | C10: ='All scales all studies'!R12 -> 0 | D10: ='All scales all studies'!S12 -> 0 | E10: ='All scales all studies'!T12 -> X | F10: ='All scales all studies'!U12 -> X | G10: ='All scales all studies'!V12 -> X
A11: Has an emotional supporter | B11: X | C11: ='All scales all studies'!R18 -> 0 | D11: ='All scales all studies'!S18 -> X | E11: ='All scales all studies'!T18 -> X | F11: ='All scales all studies'!U18 -> 0 | G11: ='All scales all studies'!V18 -> X
A12: Has someone they can trust/confidant | B12: X | C12: ='All scales all studies'!R14 -> X | D12: ='All scales all studies'!S14 -> X | E12: ='All scales all studies'!T14 -> X | F12: ='All scales all studies'!U14 -> X | G12: ='All scales all studies'!V14 -> X
C13: =COUNTIF(C2:C12,"X")/COUNTIF($B2:$B12,"X") -> 0.63636364 | D13: =COUNTIF(D2:D12,"X")/COUNTIF($B2:$B12,"X") -> 0.81818182 | E13: =COUNTIF(E2:E12,"X")/COUNTIF($B2:$B12,"X") -> 1 | F13: =COUNTIF(F2:F12,"X")/COUNTIF($B2:$B12,"X") -> 0.90909091 | G13: =COUNTIF(G2:G12,"X")/COUNTIF($B2:$B12,"X") -> 0.54545455

Sheet Makizako
B1: Makizako | C1: ARIC | D1: CHS | E1: FHS | F1: JHS | G1: MESA
A2: Miss people | B2: X | C2: ='All scales all studies'!R10 -> X | D2: ='All scales all studies'!S10 -> X | E2: ='All scales all studies'!T10 -> X | F2: ='All scales all studies'!U10 -> X | G2: ='All scales all studies'!V10 -> X
A3: Help others in need | B3: X | C3: ='All scales all studies'!R32 -> X | D3: ='All scales all studies'!S32 -> X | E3: ='All scales all studies'!T32 -> 0 | F3: ='All scales all studies'!U32 -> X | G3: ='All scales all studies'!V32 -> 0
A4: Going out | B4: X | C4: ='All scales all studies'!R23 -> 0 | D4: ='All scales all studies'!S23 -> 0 | E4: ='All scales all studies'!T23 -> 0 | F4: ='All scales all studies'!U23 -> 0 | G4: ='All scales all studies'!V23 -> 0
A5: Visiting friends | B5: X | C5: ='All scales all studies'!R22 -> 0 | D5: ='All scales all studies'!S22 -> 0 | E5: ='All scales all studies'!T22 -> 0 | F5: ='All scales all studies'!U22 -> 0 | G5: ='All scales all studies'!V22 -> 0
A6: Talking with someone exery day | B6: X | C6: ='All scales all studies'!R2 -> 0 | D6: ='All scales all studies'!S2 -> 0 | E6: ='All scales all studies'!T2 -> 0 | F6: ='All scales all studies'!U2 -> 0 | G6: ='All scales all studies'!V2 -> 0
C7: =COUNTIF(C2:C6,"X")/COUNTIF($B2:$B6,"X") -> 0.4 | D7: =COUNTIF(D2:D6,"X")/COUNTIF($B2:$B6,"X") -> 0.4 | E7: =COUNTIF(E2:E6,"X")/COUNTIF($B2:$B6,"X") -> 0.2 | F7: =COUNTIF(F2:F6,"X")/COUNTIF($B2:$B6,"X") -> 0.4 | G7: =COUNTIF(G2:G6,"X")/COUNTIF($B2:$B6,"X") -> 0.2

Sheet Lubben SNS
C1: ARIC | D1: CHS | E1: FHS | F1: JHS | G1: MESA
A2: ='All scales all studies'!A4 -> # Close friends | B2: ='All scales all studies'!P4 -> X | C2: ='All scales all studies'!R4 -> X | D2: ='All scales all studies'!S4 -> X | E2: ='All scales all studies'!T4 -> X | F2: ='All scales all studies'!U4 -> X | G2: ='All scales all studies'!V4 -> 0
A3: ='All scales all studies'!A5 -> # Close friends/mo | B3: ='All scales all studies'!P5 -> X | C3: ='All scales all studies'!R5 -> X | D3: ='All scales all studies'!S5 -> X | E3: ='All scales all studies'!T5 -> X | F3: ='All scales all studies'!U5 -> X | G3: ='All scales all studies'!V5 -> 0
A4: ='All scales all studies'!A6 -> How often see friend with most contact? | B4: ='All scales all studies'!P6 -> X | C4: ='All scales all studies'!R6 -> X | D4: ='All scales all studies'!S6 -> X | E4: ='All scales all studies'!T6 -> 0 | F4: ='All scales all studies'!U6 -> 0 | G4: ='All scales all studies'!V6 -> 0
A5: ='All scales all studies'!A7 -> # close relatives | B5: ='All scales all studies'!P7 -> X | C5: ='All scales all studies'!R7 -> X | D5: ='All scales all studies'!S7 -> X | E5: ='All scales all studies'!T7 -> X | F5: ='All scales all studies'!U7 -> X | G5: ='All scales all studies'!V7 -> 0
A6: ='All scales all studies'!A8 -> # relatives once/month | B6: ='All scales all studies'!P8 -> X | C6: ='All scales all studies'!R8 -> X | D6: ='All scales all studies'!S8 -> X | E6: ='All scales all studies'!T8 -> X | F6: ='All scales all studies'!U8 -> X | G6: ='All scales all studies'!V8 -> 0
A7: ='All scales all studies'!A9 -> How often see relative with most contaact | B7: ='All scales all studies'!P9 -> X | C7: ='All scales all studies'!R9 -> X | D7: ='All scales all studies'!S9 -> X | E7: ='All scales all studies'!T9 -> 0 | F7: ='All scales all studies'!U9 -> X | G7: ='All scales all studies'!V9 -> 0
A8: ='All scales all studies'!A14 -> Trust at least one person's advice | B8: ='All scales all studies'!P14 -> X | C8: ='All scales all studies'!R14 -> X | D8: ='All scales all studies'!S14 -> X | E8: ='All scales all studies'!T14 -> X | F8: ='All scales all studies'!U14 -> X | G8: ='All scales all studies'!V14 -> X
A9: ='All scales all studies'!A16 -> Has someone who can help with a serious/personal problem. | B9: ='All scales all studies'!P16 -> X | C9: ='All scales all studies'!R16 -> X | D9: ='All scales all studies'!S16 -> X | E9: ='All scales all studies'!T16 -> X | F9: ='All scales all studies'!U16 -> X | G9: ='All scales all studies'!V16 -> X
A10: ='All scales all studies'!A17 -> Has someone they can trust/confidant | B10: ='All scales all studies'!P17 -> X | C10: ='All scales all studies'!R17 -> X | D10: ='All scales all studies'!S17 -> X | E10: ='All scales all studies'!T17 -> X | F10: ='All scales all studies'!U17 -> 0 | G10: ='All scales all studies'!V17 -> X
A11: ='All scales all studies'!A30 -> Others talk to you about important decisions | B11: ='All scales all studies'!P30 -> X | C11: ='All scales all studies'!R30 -> X | D11: ='All scales all studies'!S30 -> X | E11: ='All scales all studies'!T30 -> 0 | F11: ='All scales all studies'!U30 -> 0 | G11: ='All scales all studies'!V30 -> 0
A12: ='All scales all studies'!A32 -> Helps others in need | B12: ='All scales all studies'!P32 -> X | C12: ='All scales all studies'!R32 -> X | D12: ='All scales all studies'!S32 -> X | E12: ='All scales all studies'!T32 -> 0 | F12: ='All scales all studies'!U32 -> X | G12: ='All scales all studies'!V32 -> 0
C13: =COUNTIF(C2:C12,"X")/COUNTIF($B2:$B12,"X") -> 1 | D13: =COUNTIF(D2:D12,"X")/COUNTIF($B2:$B12,"X") -> 1 | E13: =COUNTIF(E2:E12,"X")/COUNTIF($B2:$B12,"X") -> 0.63636364 | F13: =COUNTIF(F2:F12,"X")/COUNTIF($B2:$B12,"X") -> 0.72727273 | G13: =COUNTIF(G2:G12,"X")/COUNTIF($B2:$B12,"X") -> 0.27272727

Sheet FRAIL
B1: FRAIL | C1: ARIC | D1: CHS | E1: FHS | F1: JHS | G1: MESA
A2: ='All scales all studies'!A44 -> Everything an effort (CESD) | B2: ='All scales all studies'!I44 -> X | C2: ='All scales all studies'!R44 -> X | D2: ='All scales all studies'!S44 -> X | E2: ='All scales all studies'!T44 -> X | F2: ='All scales all studies'!U44 -> X | G2: ='All scales all studies'!V44 -> X
A3: ='All scales all studies'!A45 -> Couldn't get going (CESD) | B3: ='All scales all studies'!I45 -> X | C3: ='All scales all studies'!R45 -> X | D3: ='All scales all studies'!S45 -> X | E3: ='All scales all studies'!T45 -> X | F3: ='All scales all studies'!U45 -> X | G3: ='All scales all studies'!V45 -> X
A4: ='All scales all studies'!A52 -> Able to walk up one flight (resistance) | B4: ='All scales all studies'!I52 -> X | C4: ='All scales all studies'!R52 -> X | D4: ='All scales all studies'!S52 -> X | E4: ='All scales all studies'!T52 -> X | F4: ='All scales all studies'!U52 -> X | G4: ='All scales all studies'!V52 -> X
A5: ='All scales all studies'!A54 -> Able to walk 1/2 mile (self-report) | B5: ='All scales all studies'!I54 -> X | C5: ='All scales all studies'!R54 -> X | D5: ='All scales all studies'!S54 -> X | E5: ='All scales all studies'!T54 -> X | F5: ='All scales all studies'!U54 -> X | G5: ='All scales all studies'!V54 -> X
A6: ='All scales all studies'!A59 -> Weight loss in past year | B6: ='All scales all studies'!I59 -> X | C6: ='All scales all studies'!R59 -> X | D6: ='All scales all studies'!S59 -> X | E6: ='All scales all studies'!T59 -> X | F6: ='All scales all studies'!U59 -> X | G6: ='All scales all studies'!V59 -> X
A7: ='All scales all studies'!A73 -> DM | B7: ='All scales all studies'!I73 -> X | C7: ='All scales all studies'!R73 -> X | D7: ='All scales all studies'!S73 -> X | E7: ='All scales all studies'!T73 -> X | F7: ='All scales all studies'!U73 -> X | G7: ='All scales all studies'!V73 -> X
A8: ='All scales all studies'!A74 -> HTN | B8: ='All scales all studies'!I74 -> X | C8: ='All scales all studies'!R74 -> X | D8: ='All scales all studies'!S74 -> X | E8: ='All scales all studies'!T74 -> X | F8: ='All scales all studies'!U74 -> X | G8: ='All scales all studies'!V74 -> X
A9: ='All scales all studies'!A75 -> COPD | B9: ='All scales all studies'!I75 -> X | C9: ='All scales all studies'!R75 -> X | D9: ='All scales all studies'!S75 -> X | E9: ='All scales all studies'!T75 -> X | F9: ='All scales all studies'!U75 -> X | G9: ='All scales all studies'!V75 -> X
A10: ='All scales all studies'!A76 -> Asthma | B10: ='All scales all studies'!I76 -> X | C10: ='All scales all studies'!R76 -> X | D10: ='All scales all studies'!S76 -> X | E10: ='All scales all studies'!T76 -> X | F10: ='All scales all studies'!U76 -> X | G10: ='All scales all studies'!V76 -> X
A11: ='All scales all studies'!A77 -> DJD | B11: ='All scales all studies'!I77 -> X | C11: ='All scales all studies'!R77 -> X | D11: ='All scales all studies'!S77 -> X | E11: ='All scales all studies'!T77 -> X | F11: ='All scales all studies'!U77 -> 0 | G11: ='All scales all studies'!V77 -> X
A12: ='All scales all studies'!A78 -> CKD | B12: ='All scales all studies'!I78 -> X | C12: ='All scales all studies'!R78 -> X | D12: ='All scales all studies'!S78 -> X | E12: ='All scales all studies'!T78 -> X | F12: ='All scales all studies'!U78 -> X | G12: ='All scales all studies'!V78 -> X
A13: ='All scales all studies'!A79 -> CHF | B13: ='All scales all studies'!I79 -> X | C13: ='All scales all studies'!R79 -> X | D13: ='All scales all studies'!S79 -> X | E13: ='All scales all studies'!T79 -> X | F13: ='All scales all studies'!U79 -> X | G13: ='All scales all studies'!V79 -> X
A14: ='All scales all studies'!A80 -> CAD | B14: ='All scales all studies'!I80 -> X | C14: ='All scales all studies'!R80 -> X | D14: ='All scales all studies'!S80 -> X | E14: ='All scales all studies'!T80 -> X | F14: ='All scales all studies'!U80 -> X | G14: ='All scales all studies'!V80 -> X
A15: ='All scales all studies'!A81 -> CVA | B15: ='All scales all studies'!I81 -> X | C15: ='All scales all studies'!R81 -> X | D15: ='All scales all studies'!S81 -> X | E15: ='All scales all studies'!T81 -> X | F15: ='All scales all studies'!U81 -> X | G15: ='All scales all studies'!V81 -> X
A16: ='All scales all studies'!A82 -> Cancer | B16: ='All scales all studies'!I82 -> X | C16: ='All scales all studies'!R82 -> X | D16: ='All scales all studies'!S82 -> X | E16: ='All scales all studies'!T82 -> X | F16: ='All scales all studies'!U82 -> X | G16: ='All scales all studies'!V82 -> X
C17: =COUNTIF(C2:C16,"X")/COUNTIF($B2:$B16,"X") -> 1 | D17: =COUNTIF(D2:D16,"X")/COUNTIF($B2:$B16,"X") -> 1 | E17: =COUNTIF(E2:E16,"X")/COUNTIF($B2:$B16,"X") -> 1 | F17: =COUNTIF(F2:F16,"X")/COUNTIF($B2:$B16,"X") -> 0.93333333 | G17: =COUNTIF(G2:G16,"X")/COUNTIF($B2:$B16,"X") -> 1

Sheet Fried
B1: Fried | C1: ARIC | D1: CHS | E1: FHS | F1: JHS | G1: MESA
A2: ='All scales all studies'!A44 -> Everything an effort (CESD) | B2: ='All scales all studies'!J44 -> X | C2: ='All scales all studies'!R44 -> X | D2: ='All scales all studies'!S44 -> X | E2: ='All scales all studies'!T44 -> X | F2: ='All scales all studies'!U44 -> X | G2: ='All scales all studies'!V44 -> X
A3: ='All scales all studies'!A45 -> Couldn't get going (CESD) | B3: ='All scales all studies'!J45 -> X | C3: ='All scales all studies'!R45 -> X | D3: ='All scales all studies'!S45 -> X | E3: ='All scales all studies'!T45 -> X | F3: ='All scales all studies'!U45 -> X | G3: ='All scales all studies'!V45 -> X
A4: ='All scales all studies'!A49 -> Physical activity (kcal/day, self-report) | B4: ='All scales all studies'!J49 -> X | C4: ='All scales all studies'!R49 -> X | D4: ='All scales all studies'!S49 -> X | E4: ='All scales all studies'!T49 -> X | F4: ='All scales all studies'!U49 -> X | G4: ='All scales all studies'!V49 -> X
A5: ='All scales all studies'!A55 -> Gait speed (measured) | B5: ='All scales all studies'!J55 -> X | C5: ='All scales all studies'!R55 -> X | D5: ='All scales all studies'!S55 -> X | E5: ='All scales all studies'!T55 -> X | F5: ='All scales all studies'!U55 -> 0 | G5: ='All scales all studies'!V55 -> 0
A6: ='All scales all studies'!A56 -> Grip strength (measured) | B6: ='All scales all studies'!J56 -> X | C6: ='All scales all studies'!R56 -> X | D6: ='All scales all studies'!S56 -> X | E6: ='All scales all studies'!T56 -> X | F6: ='All scales all studies'!U56 -> 0 | G6: ='All scales all studies'!V56 -> 0
A7: ='All scales all studies'!A59 -> Weight loss in past year | B7: ='All scales all studies'!J59 -> X | C7: ='All scales all studies'!R59 -> X | D7: ='All scales all studies'!S59 -> X | E7: ='All scales all studies'!T59 -> X | F7: ='All scales all studies'!U59 -> X | G7: ='All scales all studies'!V59 -> X
C8: =COUNTIF(C2:C7,"X")/COUNTIF($B2:$B7,"X") -> 1 | D8: =COUNTIF(D2:D7,"X")/COUNTIF($B2:$B7,"X") -> 1 | E8: =COUNTIF(E2:E7,"X")/COUNTIF($B2:$B7,"X") -> 1 | F8: =COUNTIF(F2:F7,"X")/COUNTIF($B2:$B7,"X") -> 0.66666667 | G8: =COUNTIF(G2:G7,"X")/COUNTIF($B2:$B7,"X") -> 0.66666667

Sheet Rockwood
B1: Rockwood | C1: ARIC | D1: CHS | E1: FHS | F1: JHS | G1: MESA
A2: ='All scales all studies'!A44 -> Everything an effort (CESD) | B2: ='All scales all studies'!K44 -> X | C2: ='All scales all studies'!R44 -> X | D2: ='All scales all studies'!S44 -> X | E2: ='All scales all studies'!T44 -> X | F2: ='All scales all studies'!U44 -> X | G2: ='All scales all studies'!V44 -> X
A3: ='All scales all studies'!A45 -> Couldn't get going (CESD) | B3: ='All scales all studies'!K45 -> X | C3: ='All scales all studies'!R45 -> X | D3: ='All scales all studies'!S45 -> X | E3: ='All scales all studies'!T45 -> X | F3: ='All scales all studies'!U45 -> X | G3: ='All scales all studies'!V45 -> X
A4: ='All scales all studies'!A48 -> Able to do moderate activity | B4: ='All scales all studies'!K48 -> X | C4: ='All scales all studies'!R48 -> X | D4: ='All scales all studies'!S48 -> X | E4: ='All scales all studies'!T48 -> X | F4: ='All scales all studies'!U48 -> X | G4: ='All scales all studies'!V48 -> 0
A5: ='All scales all studies'!A52 -> Able to walk up one flight (resistance) | B5: ='All scales all studies'!K52 -> X | C5: ='All scales all studies'!R52 -> X | D5: ='All scales all studies'!S52 -> X | E5: ='All scales all studies'!T52 -> X | F5: ='All scales all studies'!U52 -> X | G5: ='All scales all studies'!V52 -> X
A6: ='All scales all studies'!A53 -> Can walk up several flights (self-report) | B6: ='All scales all studies'!K53 -> X | C6: ='All scales all studies'!R53 -> X | D6: ='All scales all studies'!S53 -> X | E6: ='All scales all studies'!T53 -> X | F6: ='All scales all studies'!U53 -> 0 | G6: ='All scales all studies'!V53 -> 0
A7: ='All scales all studies'!A54 -> Able to walk 1/2 mile (self-report) | B7: ='All scales all studies'!K54 -> X | C7: ='All scales all studies'!R54 -> X | D7: ='All scales all studies'!S54 -> X | E7: ='All scales all studies'!T54 -> X | F7: ='All scales all studies'!U54 -> X | G7: ='All scales all studies'!V54 -> X
A8: ='All scales all studies'!A55 -> Gait speed (measured) | B8: ='All scales all studies'!K55 -> X | C8: ='All scales all studies'!R55 -> X | D8: ='All scales all studies'!S55 -> X | E8: ='All scales all studies'!T55 -> X | F8: ='All scales all studies'!U55 -> 0 | G8: ='All scales all studies'!V55 -> 0
A9: ='All scales all studies'!A56 -> Grip strength (measured) | B9: ='All scales all studies'!K56 -> X | C9: ='All scales all studies'!R56 -> X | D9: ='All scales all studies'!S56 -> X | E9: ='All scales all studies'!T56 -> X | F9: ='All scales all studies'!U56 -> 0 | G9: ='All scales all studies'!V56 -> 0
A10: ='All scales all studies'!A58 -> BMI | B10: ='All scales all studies'!K58 -> X | C10: ='All scales all studies'!R58 -> X | D10: ='All scales all studies'!S58 -> X | E10: ='All scales all studies'!T58 -> X | F10: ='All scales all studies'!U58 -> X | G10: ='All scales all studies'!V58 -> X
A11: ='All scales all studies'!A59 -> Weight loss in past year | B11: ='All scales all studies'!K59 -> X | C11: ='All scales all studies'!R59 -> X | D11: ='All scales all studies'!S59 -> X | E11: ='All scales all studies'!T59 -> X | F11: ='All scales all studies'!U59 -> X | G11: ='All scales all studies'!V59 -> X
A12: ='All scales all studies'!A65 -> Felt nervous/anxious (last month) | B12: ='All scales all studies'!K65 -> X | C12: ='All scales all studies'!R65 -> X | D12: ='All scales all studies'!S65 -> X | E12: ='All scales all studies'!T65 -> X | F12: ='All scales all studies'!U65 -> X | G12: ='All scales all studies'!V65 -> X
A13: ='All scales all studies'!A66 -> How often do you feel able to cope with problems (last month) | B13: ='All scales all studies'!K66 -> X | C13: ='All scales all studies'!R66 -> X | D13: ='All scales all studies'!S66 -> X | E13: ='All scales all studies'!T66 -> 0 | F13: ='All scales all studies'!U66 -> X | G13: ='All scales all studies'!V66 -> X
A14: ='All scales all studies'!A69 -> Health affects activities/activity level | B14: ='All scales all studies'!K69 -> X | C14: ='All scales all studies'!R69 -> X | D14: ='All scales all studies'!S69 -> 0 | E14: ='All scales all studies'!T69 -> X | F14: ='All scales all studies'!U69 -> X | G14: ='All scales all studies'!V69 -> 0
A15: ='All scales all studies'!A70 -> Pain interferes with ability to work | B15: ='All scales all studies'!K70 -> X | C15: ='All scales all studies'!R70 -> X | D15: ='All scales all studies'!S70 -> 0 | E15: ='All scales all studies'!T70 -> X | F15: ='All scales all studies'!U70 -> 0 | G15: ='All scales all studies'!V70 -> 0
A16: ='All scales all studies'!A71 -> Physical/emotional probs affect social activities | B16: ='All scales all studies'!K71 -> X | C16: ='All scales all studies'!R71 -> X | D16: ='All scales all studies'!S71 -> 0 | E16: ='All scales all studies'!T71 -> X | F16: ='All scales all studies'!U71 -> X | G16: ='All scales all studies'!V71 -> 0
A17: ='All scales all studies'!A73 -> DM | B17: ='All scales all studies'!K73 -> X | C17: ='All scales all studies'!R73 -> X | D17: ='All scales all studies'!S73 -> X | E17: ='All scales all studies'!T73 -> X | F17: ='All scales all studies'!U73 -> X | G17: ='All scales all studies'!V73 -> X
A18: ='All scales all studies'!A74 -> HTN | B18: ='All scales all studies'!K74 -> X | C18: ='All scales all studies'!R74 -> X | D18: ='All scales all studies'!S74 -> X | E18: ='All scales all studies'!T74 -> X | F18: ='All scales all studies'!U74 -> X | G18: ='All scales all studies'!V74 -> X
A19: ='All scales all studies'!A75 -> COPD | B19: ='All scales all studies'!K75 -> X | C19: ='All scales all studies'!R75 -> X | D19: ='All scales all studies'!S75 -> X | E19: ='All scales all studies'!T75 -> X | F19: ='All scales all studies'!U75 -> X | G19: ='All scales all studies'!V75 -> X
A20: ='All scales all studies'!A76 -> Asthma | B20: ='All scales all studies'!K76 -> X | C20: ='All scales all studies'!R76 -> X | D20: ='All scales all studies'!S76 -> X | E20: ='All scales all studies'!T76 -> X | F20: ='All scales all studies'!U76 -> X | G20: ='All scales all studies'!V76 -> X
A21: ='All scales all studies'!A77 -> DJD | B21: ='All scales all studies'!K77 -> X | C21: ='All scales all studies'!R77 -> X | D21: ='All scales all studies'!S77 -> X | E21: ='All scales all studies'!T77 -> X | F21: ='All scales all studies'!U77 -> 0 | G21: ='All scales all studies'!V77 -> X
A22: ='All scales all studies'!A78 -> CKD | B22: ='All scales all studies'!K78 -> X | C22: ='All scales all studies'!R78 -> X | D22: ='All scales all studies'!S78 -> X | E22: ='All scales all studies'!T78 -> X | F22: ='All scales all studies'!U78 -> X | G22: ='All scales all studies'!V78 -> X
A23: ='All scales all studies'!A79 -> CHF | B23: ='All scales all studies'!K79 -> X | C23: ='All scales all studies'!R79 -> X | D23: ='All scales all studies'!S79 -> X | E23: ='All scales all studies'!T79 -> X | F23: ='All scales all studies'!U79 -> X | G23: ='All scales all studies'!V79 -> X
A24: ='All scales all studies'!A80 -> CAD | B24: ='All scales all studies'!K80 -> X | C24: ='All scales all studies'!R80 -> X | D24: ='All scales all studies'!S80 -> X | E24: ='All scales all studies'!T80 -> X | F24: ='All scales all studies'!U80 -> X | G24: ='All scales all studies'!V80 -> X
A25: ='All scales all studies'!A81 -> CVA | B25: ='All scales all studies'!K81 -> X | C25: ='All scales all studies'!R81 -> X | D25: ='All scales all studies'!S81 -> X | E25: ='All scales all studies'!T81 -> X | F25: ='All scales all studies'!U81 -> X | G25: ='All scales all studies'!V81 -> X
A26: ='All scales all studies'!A82 -> Cancer | B26: ='All scales all studies'!K82 -> X | C26: ='All scales all studies'!R82 -> X | D26: ='All scales all studies'!S82 -> X | E26: ='All scales all studies'!T82 -> X | F26: ='All scales all studies'!U82 -> X | G26: ='All scales all studies'!V82 -> X
A27: ='All scales all studies'!A83 -> Fracture (osteoporosis) | B27: ='All scales all studies'!K83 -> X | C27: ='All scales all studies'!R83 -> X | D27: ='All scales all studies'!S83 -> X | E27: ='All scales all studies'!T83 -> X | F27: ='All scales all studies'!U83 -> 0 | G27: ='All scales all studies'!V83 -> 0
A28: ='All scales all studies'!A85 -> Dressing | B28: ='All scales all studies'!K85 -> X | C28: ='All scales all studies'!R85 -> X | D28: ='All scales all studies'!S85 -> X | E28: ='All scales all studies'!T85 -> X | F28: ='All scales all studies'!U85 -> 0 | G28: ='All scales all studies'!V85 -> 0
A29: ='All scales all studies'!A86 -> Bathing | B29: ='All scales all studies'!K86 -> X | C29: ='All scales all studies'!R86 -> X | D29: ='All scales all studies'!S86 -> X | E29: ='All scales all studies'!T86 -> X | F29: ='All scales all studies'!U86 -> 0 | G29: ='All scales all studies'!V86 -> 0
A30: ='All scales all studies'!A87 -> Transferring | B30: ='All scales all studies'!K87 -> X | C30: ='All scales all studies'!R87 -> X | D30: ='All scales all studies'!S87 -> X | E30: ='All scales all studies'!T87 -> X | F30: ='All scales all studies'!U87 -> 0 | G30: ='All scales all studies'!V87 -> 0
A31: ='All scales all studies'!A88 -> Toileting | B31: ='All scales all studies'!K88 -> X | C31: ='All scales all studies'!R88 -> 0 | D31: ='All scales all studies'!S88 -> X | E31: ='All scales all studies'!T88 -> X | F31: ='All scales all studies'!U88 -> 0 | G31: ='All scales all studies'!V88 -> 0
A32: ='All scales all studies'!A92 -> Able to do heavy work around the house | B32: ='All scales all studies'!K92 -> X | C32: ='All scales all studies'!R92 -> X | D32: ='All scales all studies'!S92 -> X | E32: ='All scales all studies'!T92 -> X | F32: ='All scales all studies'!U92 -> X | G32: ='All scales all studies'!V92 -> X
A33: ='All scales all studies'!A95 -> MMSE | B33: ='All scales all studies'!K95 -> X | C33: ='All scales all studies'!R95 -> X | D33: ='All scales all studies'!S95 -> X | E33: ='All scales all studies'!T95 -> X | F33: ='All scales all studies'!U95 -> 0 | G33: ='All scales all studies'!V95 -> CASI
A34: ='All scales all studies'!A97 -> Nursing home | B34: ='All scales all studies'!K97 -> X | C34: ='All scales all studies'!R97 -> X | D34: ='All scales all studies'!S97 -> X | E34: ='All scales all studies'!T97 -> X | F34: ='All scales all studies'!U97 -> X | G34: ='All scales all studies'!V97 -> 0
C35: =COUNTIF(C2:C34,"X")/COUNTIF($B2:$B34,"X") -> 0.96969697 | D35: =COUNTIF(D2:D34,"X")/COUNTIF($B2:$B34,"X") -> 0.90909091 | E35: =COUNTIF(E2:E34,"X")/COUNTIF($B2:$B34,"X") -> 0.96969697 | F35: =COUNTIF(F2:F34,"X")/COUNTIF($B2:$B34,"X") -> 0.66666667 | G35: =COUNTIF(G2:G34,"X")/COUNTIF($B2:$B34,"X") -> 0.57575758

Sheet Tilburg
C1: ARIC | D1: CHS | E1: FHS | F1: JHS | G1: MESA
A2: ='All scales all studies'!A10 -> Misses people/lonely | B2: ='All scales all studies'!O10 -> X | C2: ='All scales all studies'!R10 -> X | D2: ='All scales all studies'!S10 -> X | E2: ='All scales all studies'!T10 -> X | F2: ='All scales all studies'!U10 -> X | G2: ='All scales all studies'!V10 -> X
A3: ='All scales all studies'!A19 -> Receives enough support from others | B3: ='All scales all studies'!O19 -> X | C3: ='All scales all studies'!R19 -> 0 | D3: ='All scales all studies'!S19 -> 0 | E3: ='All scales all studies'!T19 -> 0 | F3: ='All scales all studies'!U19 -> X | G3: ='All scales all studies'!V19 -> 0
A4: ='All scales all studies'!A39 -> Lives alone | B4: ='All scales all studies'!O39 -> X | C4: ='All scales all studies'!R39 -> X | D4: ='All scales all studies'!S39 -> X | E4: ='All scales all studies'!T39 -> X | F4: ='All scales all studies'!U39 -> X | G4: ='All scales all studies'!V39 -> 0
A5: ='All scales all studies'!A43 -> Feel physically healthy | B5: ='All scales all studies'!O43 -> X | C5: ='All scales all studies'!R43 -> X | D5: ='All scales all studies'!S43 -> X | E5: ='All scales all studies'!T43 -> X | F5: ='All scales all studies'!U43 -> X | G5: ='All scales all studies'!V43 -> X
A6: ='All scales all studies'!A46 -> Has poor vision | B6: ='All scales all studies'!O46 -> X | C6: ='All scales all studies'!R46 -> X | D6: ='All scales all studies'!S46 -> X | E6: ='All scales all studies'!T46 -> X | F6: ='All scales all studies'!U46 -> 0 | G6: ='All scales all studies'!V46 -> 0
A7: ='All scales all studies'!A47 -> Has poor hearing | B7: ='All scales all studies'!O47 -> X | C7: ='All scales all studies'!R47 -> X | D7: ='All scales all studies'!S47 -> X | E7: ='All scales all studies'!T47 -> X | F7: ='All scales all studies'!U47 -> 0 | G7: ='All scales all studies'!V47 -> 0
A8: ='All scales all studies'!A50 -> Has difficulty walking (self-report) | B8: ='All scales all studies'!O50 -> X | C8: ='All scales all studies'!R50 -> X | D8: ='All scales all studies'!S50 -> X | E8: ='All scales all studies'!T50 -> X | F8: ='All scales all studies'!U50 -> X | G8: ='All scales all studies'!V50 -> 0
A9: ='All scales all studies'!A51 -> Has difficulty w balance (self-report) | B9: ='All scales all studies'!O51 -> X | C9: ='All scales all studies'!R51 -> X | D9: ='All scales all studies'!S51 -> X | E9: ='All scales all studies'!T51 -> X | F9: ='All scales all studies'!U51 -> 0 | G9: ='All scales all studies'!V51 -> 0
A10: ='All scales all studies'!A56 -> Grip strength (measured) | B10: ='All scales all studies'!O56 -> X | C10: ='All scales all studies'!R56 -> X | D10: ='All scales all studies'!S56 -> X | E10: ='All scales all studies'!T56 -> X | F10: ='All scales all studies'!U56 -> 0 | G10: ='All scales all studies'!V56 -> 0
A11: ='All scales all studies'!A59 -> Weight loss in past year | B11: ='All scales all studies'!O59 -> X | C11: ='All scales all studies'!R59 -> X | D11: ='All scales all studies'!S59 -> X | E11: ='All scales all studies'!T59 -> X | F11: ='All scales all studies'!U59 -> X | G11: ='All scales all studies'!V59 -> X
A12: ='All scales all studies'!A64 -> Felt down (last month) | B12: ='All scales all studies'!O64 -> X | C12: ='All scales all studies'!R64 -> X | D12: ='All scales all studies'!S64 -> X | E12: ='All scales all studies'!T64 -> X | F12: ='All scales all studies'!U64 -> X | G12: ='All scales all studies'!V64 -> X
A13: ='All scales all studies'!A65 -> Felt nervous/anxious (last month) | B13: ='All scales all studies'!O65 -> X | C13: ='All scales all studies'!R65 -> X | D13: ='All scales all studies'!S65 -> X | E13: ='All scales all studies'!T65 -> X | F13: ='All scales all studies'!U65 -> X | G13: ='All scales all studies'!V65 -> X
A14: ='All scales all studies'!A66 -> How often do you feel able to cope with problems (last month) | B14: ='All scales all studies'!O66 -> X | C14: ='All scales all studies'!R66 -> X | D14: ='All scales all studies'!S66 -> X | E14: ='All scales all studies'!T66 -> 0 | F14: ='All scales all studies'!U66 -> X | G14: ='All scales all studies'!V66 -> X
A15: ='All scales all studies'!A94 -> Memory problems (self-report) | B15: ='All scales all studies'!O94 -> X | C15: ='All scales all studies'!R94 -> X | D15: ='All scales all studies'!S94 -> X | E15: ='All scales all studies'!T94 -> X | F15: ='All scales all studies'!U94 -> 0 | G15: ='All scales all studies'!V94 -> 0
C16: =COUNTIF(C2:C15,"X")/COUNTIF($B2:$B15,"X") -> 0.92857143 | D16: =COUNTIF(D2:D15,"X")/COUNTIF($B2:$B15,"X") -> 0.92857143 | E16: =COUNTIF(E2:E15,"X")/COUNTIF($B2:$B15,"X") -> 0.85714286 | F16: =COUNTIF(F2:F15,"X")/COUNTIF($B2:$B15,"X") -> 0.64285714 | G16: =COUNTIF(G2:G15,"X")/COUNTIF($B2:$B15,"X") -> 0.42857143

Sheet FIFE
C1: ARIC | D1: CHS | E1: FHS | F1: JHS | G1: MESA
A2: ='All scales all studies'!A43 -> Feel physically healthy | B2: ='All scales all studies'!N43 -> X | C2: ='All scales all studies'!R43 -> X | D2: ='All scales all studies'!S43 -> X | E2: ='All scales all studies'!T43 -> X | F2: ='All scales all studies'!U43 -> X | G2: ='All scales all studies'!V43 -> X
A3: ='All scales all studies'!A44 -> Everything an effort (CESD) | B3: ='All scales all studies'!N44 -> X | C3: ='All scales all studies'!R44 -> X | D3: ='All scales all studies'!S44 -> X | E3: ='All scales all studies'!T44 -> X | F3: ='All scales all studies'!U44 -> X | G3: ='All scales all studies'!V44 -> X
A4: ='All scales all studies'!A45 -> Couldn't get going (CESD) | B4: ='All scales all studies'!N45 -> X | C4: ='All scales all studies'!R45 -> X | D4: ='All scales all studies'!S45 -> X | E4: ='All scales all studies'!T45 -> X | F4: ='All scales all studies'!U45 -> X | G4: ='All scales all studies'!V45 -> X
A5: ='All scales all studies'!A59 -> Weight loss in past year | B5: ='All scales all studies'!N59 -> X | C5: ='All scales all studies'!R59 -> X | D5: ='All scales all studies'!S59 -> X | E5: ='All scales all studies'!T59 -> X | F5: ='All scales all studies'!U59 -> X | G5: ='All scales all studies'!V59 -> X
A6: ='All scales all studies'!A60 -> Poor appetite | B6: ='All scales all studies'!N60 -> X | C6: ='All scales all studies'!R60 -> X | D6: ='All scales all studies'!S60 -> X | E6: ='All scales all studies'!T60 -> X | F6: ='All scales all studies'!U60 -> X | G6: ='All scales all studies'!V60 -> X
A7: ='All scales all studies'!A61 -> Tooth/mouth problems affect eating | B7: ='All scales all studies'!N61 -> X | C7: ='All scales all studies'!R61 -> X | D7: ='All scales all studies'!S61 -> X | E7: ='All scales all studies'!T61 -> 0 | F7: ='All scales all studies'!U61 -> 0 | G7: ='All scales all studies'!V61 -> X
A8: ='All scales all studies'!A71 -> Physical/emotional probs affect social activities | B8: ='All scales all studies'!N71 -> X | C8: ='All scales all studies'!R71 -> X | D8: ='All scales all studies'!S71 -> 0 | E8: ='All scales all studies'!T71 -> X | F8: ='All scales all studies'!U71 -> X | G8: ='All scales all studies'!V71 -> 0
A9: ='All scales all studies'!A86 -> Bathing | B9: ='All scales all studies'!N86 -> X | C9: ='All scales all studies'!R86 -> X | D9: ='All scales all studies'!S86 -> X | E9: ='All scales all studies'!T86 -> X | F9: ='All scales all studies'!U86 -> 0 | G9: ='All scales all studies'!V86 -> 0
A10: ='All scales all studies'!A87 -> Transferring | B10: ='All scales all studies'!N87 -> X | C10: ='All scales all studies'!R87 -> X | D10: ='All scales all studies'!S87 -> X | E10: ='All scales all studies'!T87 -> X | F10: ='All scales all studies'!U87 -> 0 | G10: ='All scales all studies'!V87 -> 0
A11: ='All scales all studies'!A98 -> Hospitalized last 3 months | B11: ='All scales all studies'!N98 -> X | C11: ='All scales all studies'!R98 -> X | D11: ='All scales all studies'!S98 -> X | E11: ='All scales all studies'!T98 -> X | F11: ='All scales all studies'!U98 -> X | G11: ='All scales all studies'!V98 -> X
A12: ='All scales all studies'!A99 -> ED in last 3 months | B12: ='All scales all studies'!N99 -> X | C12: ='All scales all studies'!R99 -> 0 | D12: ='All scales all studies'!S99 -> 0 | E12: ='All scales all studies'!T99 -> X | F12: ='All scales all studies'!U99 -> X | G12: ='All scales all studies'!V99 -> 0
C13: =COUNTIF(C2:C12,"X")/COUNTIF($B2:$B12,"X") -> 0.90909091 | D13: =COUNTIF(D2:D12,"X")/COUNTIF($B2:$B12,"X") -> 0.81818182 | E13: =COUNTIF(E2:E12,"X")/COUNTIF($B2:$B12,"X") -> 0.90909091 | F13: =COUNTIF(F2:F12,"X")/COUNTIF($B2:$B12,"X") -> 0.72727273 | G13: =COUNTIF(G2:G12,"X")/COUNTIF($B2:$B12,"X") -> 0.63636364

Sheet Barthe
B1: Barthe | C1: ARIC | D1: CHS | E1: FHS | F1: JHS | G1: MESA
A2: ='All scales all studies'!A52 -> Able to walk up one flight (resistance) | B2: ='All scales all studies'!L52 -> X | C2: ='All scales all studies'!R52 -> X | D2: ='All scales all studies'!S52 -> X | E2: ='All scales all studies'!T52 -> X | F2: ='All scales all studies'!U52 -> X | G2: ='All scales all studies'!V52 -> X
A3: ='All scales all studies'!A54 -> Able to walk 1/2 mile (self-report) | B3: ='All scales all studies'!L54 -> X | C3: ='All scales all studies'!R54 -> X | D3: ='All scales all studies'!S54 -> X | E3: ='All scales all studies'!T54 -> X | F3: ='All scales all studies'!U54 -> X | G3: ='All scales all studies'!V54 -> X
A4: ='All scales all studies'!A60 -> Poor appetite | B4: ='All scales all studies'!L60 -> X | C4: ='All scales all studies'!R60 -> X | D4: ='All scales all studies'!S60 -> X | E4: ='All scales all studies'!T60 -> X | F4: ='All scales all studies'!U60 -> X | G4: ='All scales all studies'!V60 -> X
A5: ='All scales all studies'!A61 -> Tooth/mouth problems affect eating | B5: ='All scales all studies'!L61 -> X | C5: ='All scales all studies'!R61 -> X | D5: ='All scales all studies'!S61 -> X | E5: ='All scales all studies'!T61 -> 0 | F5: ='All scales all studies'!U61 -> 0 | G5: ='All scales all studies'!V61 -> X
A6: ='All scales all studies'!A85 -> Dressing | B6: ='All scales all studies'!L85 -> X | C6: ='All scales all studies'!R85 -> X | D6: ='All scales all studies'!S85 -> X | E6: ='All scales all studies'!T85 -> X | F6: ='All scales all studies'!U85 -> 0 | G6: ='All scales all studies'!V85 -> 0
A7: ='All scales all studies'!A86 -> Bathing | B7: ='All scales all studies'!L86 -> X | C7: ='All scales all studies'!R86 -> X | D7: ='All scales all studies'!S86 -> X | E7: ='All scales all studies'!T86 -> X | F7: ='All scales all studies'!U86 -> 0 | G7: ='All scales all studies'!V86 -> 0
A8: ='All scales all studies'!A87 -> Transferring | B8: ='All scales all studies'!L87 -> X | C8: ='All scales all studies'!R87 -> X | D8: ='All scales all studies'!S87 -> X | E8: ='All scales all studies'!T87 -> X | F8: ='All scales all studies'!U87 -> 0 | G8: ='All scales all studies'!V87 -> 0
A9: ='All scales all studies'!A88 -> Toileting | B9: ='All scales all studies'!L88 -> X | C9: ='All scales all studies'!R88 -> 0 | D9: ='All scales all studies'!S88 -> X | E9: ='All scales all studies'!T88 -> X | F9: ='All scales all studies'!U88 -> 0 | G9: ='All scales all studies'!V88 -> 0
A10: ='All scales all studies'!A89 -> Feeding | B10: ='All scales all studies'!L89 -> X | C10: ='All scales all studies'!R89 -> X | D10: ='All scales all studies'!S89 -> X | E10: ='All scales all studies'!T89 -> X | F10: ='All scales all studies'!U89 -> 0 | G10: ='All scales all studies'!V89 -> 0
A11: ='All scales all studies'!A90 -> Bowel incontinence | B11: ='All scales all studies'!L90 -> X | C11: ='All scales all studies'!R90 -> X | D11: ='All scales all studies'!S90 -> 0 | E11: ='All scales all studies'!T90 -> X | F11: ='All scales all studies'!U90 -> 0 | G11: ='All scales all studies'!V90 -> 0
A12: ='All scales all studies'!A91 -> Bladder incontinence | B12: ='All scales all studies'!L91 -> X | C12: ='All scales all studies'!R91 -> X | D12: ='All scales all studies'!S91 -> X | E12: ='All scales all studies'!T91 -> X | F12: ='All scales all studies'!U91 -> 0 | G12: ='All scales all studies'!V91 -> 0
C13: =COUNTIF(C2:C12,"X")/COUNTIF($B2:$B12,"X") -> 0.90909091 | D13: =COUNTIF(D2:D12,"X")/COUNTIF($B2:$B12,"X") -> 0.90909091 | E13: =COUNTIF(E2:E12,"X")/COUNTIF($B2:$B12,"X") -> 0.90909091 | F13: =COUNTIF(F2:F12,"X")/COUNTIF($B2:$B12,"X") -> 0.27272727 | G13: =COUNTIF(G2:G12,"X")/COUNTIF($B2:$B12,"X") -> 0.36363636

Sheet Scales + visits
B1: Social scale 1 | C1: Scale 2
A2: CHS
A3: 1 | B3: CHS Soc support | C3: CHS Soc network
A4: 3 | B4: CHS Soc support | C4: CHS Soc network
A5: 4 | B5: CHS Soc support | C5: CHS Soc network
A6: 5 | B6: CHS Soc support | C6: CHS Soc network
A7: 6 | B7: CHS Soc support | C7: CHS Soc network
A8: 11 | B8: CHS Soc support | C8: CHS Soc network
A9: FHS Original
A10: 27 | B10: Berkman SNQ
A11: 28 | B11: Berkman SNQ
A12: 29 | B12: Berkman SNQ
A13: 30 | B13: Berkman SNQ
A14: 31 | B14: Berkman SNQ
A15: FHS Offspring/Omni1
A16: 2/7 | B16: Berkman SNQ
A17: MESA
A18: 1 | B18: ESSI
A19: 3 | B19: ESSI
A20: 4 | B20: ESSI
A21: 5 | B21: Brim Familh
A22: ARIC
A23: Visit 2 | B23: ISELF | C23: Lubben (LSNS)
A25: JHS
A26: Exam 1 | B26: ISELF | C26: Berkman

Sheet Functional activities qstnre
B1: ARIC | C1: CHS | D1: FHS | E1: JHS | F1: MESA
A2: Writing checks, paying bills, balancing checkbook
A3: Assembling tax records, business affairs, or papers
A4: Shopping alone for clothes, houshold necessities, or groceries
A5: Playing a game of skill, working on a hobby
A6: Heating water, making cup of coffee, turning stove off after use
A7: Preparing a balanced meal
A8: Keeping track of current events
A9: Paying attention to, understanding, discussing TV, book, magazine
